Workbook
Name _MailAutoSig: '2023'!$E$20
Name _MailAutoSig: '2024'!$E$20
Name _MailAutoSig: '2025'!$E$20
Name _MailAutoSig: '2026'!$E$20
Name _MailAutoSig: '2026 sandbox)'!$E$20

Sheet 2026 sandbox)
G1: 2026
A2: Forecast | C2: Jan | D2: Feb | E2: Mar | F2: Apr | G2: May | H2: Jun | I2: Jul | J2: Aug | K2: Sept | L2: Oct | M2: Nov | N2: Dec | O2: YTD Total
A3: Recurring Sales Invoiced | B3: Agreement | C3: 294517 | D3: 287630 | E3: 296845 | F3: 197915 | O3: =SUM(C3:N3) -> 1076907 | Q3: NOTES:
B4: New Agreement in Std | O4: =SUM(C4:N4) -> 0 | Q4: Agreement invoices that go out on the 8th of the month:
B5: ITMS | O5: =SUM(C5:N5) -> 0 | Q5: ARC - comprehensive services $84,000
B6: Licensing | O6: =SUM(F6:N6) -> 0 | Q6: Invoiced on 8th of month: BUNZL - de Mexico - invoiced this month for this month. Includes overages from last month. $17k
B7: Comprehensive Services | O7: =SUM(C7:N7) -> 0 | Q7: License Agreements = $38,000
B8: Other | O8: =SUM(C8:N8) -> 0
A10: New Sales Invoiced [INPUTS] | B10: Standard | C10: 106724 | D10: 147864 | E10: 126944 | F10: 49818 | O10: =SUM(C10:N10) -> 431350
B11: Miscellaneous - Invoiced | C11: 1642 | D11: 2385 | E11: 5357 | F11: 460 | O11: =SUM(C11:N11) -> 9844
B12: Credit Memo - Invoiced | C12: -630 | D12: -17761 | E12: -12220 | F12: -618 | O12: =SUM(C12:N12) -> -31229
E13: 5212
A14: Pending and Projected Sales | B14: Pending Project Milestones | F14: =5400+10250+1800 -> 17450 | G14: =1800+1800+1800 -> 5400 | H14: =1125 -> 1125 | O14: =SUM(C14:N14) -> 23975 | T14: =R20-R21-R22 -> 66787
B15: Hubspot Pipeline at 40% | O15: =SUM(C15:N15) -> 0
B16: OPPS High Forecast (inputs)
B17: OPPS Low Forecast (inputs)
A19: Total | B19: Total Revenue | C19: =C3+C10+C11+C12 -> 402253 | D19: =D3+D10+D11+D12 -> 420118 | E19: =E3+E10+E11+E12 -> 416926 | F19: =F3+F10+F11+F12 -> 247575 | G19: =G3+G10+G11+G12 -> 0 | H19: =H3+H10+H11+H12 -> 0 | I19: =I3+I10+I11+I12 -> 0 | J19: =J3+J10+J11+J12 -> 0 | ... M19: =M3+M10+M11+M12 -> 0 | N19: =N3+N6+N10+N11+N12 -> 0 | O19: =SUM(C19:N19) -> 1486872 | R19: AGREEMENT | S19: Breakdown
B20: High | C20: =C3+C5+C6+C10+C11+C16+C12 -> 402253 | D20: =D3+D5+D6+D10+D11+D16+D12 -> 420118 | E20: =E3+E5+E6+E10+E11+E16+E12+E14 -> 416926 | F20: =F19+F16 -> 247575 | G20: =G3+G5+G6+G10+G11+G16+G12+G14 -> 5400 | H20: =H3+H5+H6+H10+H11+H16+H12+H14 -> 1125 | I20: =I3+I5+I6+I10+I11+I16+I12+I14 -> 0 | J20: =J3+J5+J6+J10+J11+J16+J12+J14 -> 0 | K20: =K3+K5+K6+K7+K8+K10+K11+K12+K14+K16 -> 0 | L20: =L3+L5+L6+L7+L8+L10+L11+L12+L14+L16 -> 0 | M20: =M3+M5+M6+M7+M8+M10+M11+M12+M14+M16 -> 0 | N20: =N3+N5+N6+N7+N8+N10+N11+N12+N14+N16 -> 0 | R20: 310492 | S20: TOTAL
B21: Low | C21: =C3+C5+C6+C10+C11+C12+C17 -> 402253 | D21: =D3+D5+D6+D10+D11+D12+D17 -> 420118 | E21: =E3+E5+E6+E10+E11+E12+E17+E14 -> 416926 | F21: =F19+F17 -> 247575 | G21: =G3+G5+G6+G10+G11+G12+G17+G14 -> 5400 | H21: =H3+H5+H6+H10+H11+H12+H17+H14 -> 1125 | I21: =I3+I5+I6+I10+I11+I12+I17+I14 -> 0 | J21: =J3+J5+J6+J10+J11+J12+J17+J14 -> 0 | K21: =K3+K5+K6+K7+K8+K10+K11+K12+K14+K17 -> 0 | L21: =L3+L5+L6+L7+L8+L10+L11+L12+L14+L17 -> 0 | M21: =M3+M5+M6+M7+M8+M10+M11+M12+M14+M17 -> 0 | N21: =N3+N5+N6+N7+N8+N10+N11+N12+N14+N17 -> 0 | R21: =84424+9675 -> 94099 | S21: Comp Services + Project (BUNZL de Mex)
A22: Gap (/mo) | B22: Revenue to Goal | C22: =C19-C26 -> 2253 | D22: =D19-D26 -> 20118 | E22: =E19-E26 -> 16926 | F22: =F19-F26 -> -152425 | G22: =G19-G26 -> -400000 | H22: =H19-H26 -> -400000 | I22: =I19-I26 -> -400000 | J22: =J19-J26 -> -400000 | ... N22: =N19-N26 -> -400001 | O22: =SUM(C22:N22) -> -3313129 | R22: 149606 | S22: Managed Services
R23: =R20-R21-R22 -> 66787 | S23: Licensing/Server (Agreement)
A24: Rolling Actual/Forecast | B24: Actual | C24: =C19 -> 402253 | D24: =C24+D19 -> 822371 | E24: =D24+E19 -> 1239297 | F24: =E24+F19 -> 1486872 | G24: =F24+G19 -> 1486872 | H24: =G24+H19 -> 1486872 | I24: =H24+I19 -> 1486872 | J24: =I24+J19 -> 1486872 | K24: =J24+K19 -> 1486872 | ... N24: =M24+N19 -> 1486872 | O24: =N24 -> 1486872
B25: Actual ROLLING | C25: =C19 -> 402253 | D25: =C25+D19 -> 822371 | E25: =D25+E19 -> 1239297 | F25: =E25+F19 -> 1486872 | G25: =F25+G19 -> 1486872 | H25: =G25+H19 -> 1486872 | I25: =H25+I19 -> 1486872 | J25: =I25+J19 -> 1486872 | K25: =J25+K19 -> 1486872 | ... N25: =M25+N19 -> 1486872
A26: Monthly Goal | B26: Revenue GOAL | C26: 400000 | D26: 400000 | E26: 400000 | F26: 400000 | G26: 400000 | H26: 400000 | I26: 400000 | J26: 400000 | K26: 400000 | L26: 400000 | M26: 400000 | N26: 400001 | O26: =SUM(C26:N26) -> 4800001 | Q26: cogs | R26: rev
B27: Rolling GOAL | C27: =C26 -> 400000 | D27: =C27+D26 -> 800000 | E27: =D27+E26 -> 1200000 | F27: =E27+F26 -> 1600000 | G27: =F27+G26 -> 2000000 | H27: =G27+H26 -> 2400000 | I27: =H27+I26 -> 2800000 | J27: =I27+J26 -> 3200000 | K27: =J27+K26 -> 3600000 | ... N27: =M27+N26 -> 4800001 | O27: =N27 -> 4800001 | Q27: 55014 | R27: 84424 | S27: arc | T27: =R27-Q27 -> 29410 | U27: =T27/R27 -> 0.34836066
A28: Rolling Goal | C28: =C24-C27 -> 2253 | D28: =D24-D27 -> 22371 | E28: =E24-E27 -> 39297 | F28: =F24-F27 -> -113128 | G28: =G24-G27 -> -513128 | H28: =H24-H27 -> -913128 | I28: =I24-I27 -> -1313128 | J28: =J24-J27 -> -1713128 | ... N28: =N24-N27 -> -3313129 | O28: =N28 -> -3313129 | T28: =R28-Q28 -> 0
A29: Rolling Goal | C29: Jan | D29: Feb | E29: Mar | F29: Apr | G29: May | H29: Jun | I29: Jul | J29: Aug | K29: Sept | L29: Oct | M29: Nov | N29: Dec | O29: 2019 | T29: =R29-Q29 -> 0
A30: Rolling Goal | C30: =SUMIFS(#REF!,#REF!,1,#REF!,2019,#REF!,"open") -> #REF! | D30: =SUMIFS(#REF!,#REF!,2,#REF!,2019,#REF!,"open") -> #REF! | E30: =SUMIFS(#REF!,#REF!,3,#REF!,2019,#REF!,"open") -> #REF! | F30: =SUMIFS(#REF!,#REF!,4,#REF!,2019,#REF!,"open") -> #REF! | G30: =SUMIFS(#REF!,#REF!,5,#REF!,2019,#REF!,"open") -> #REF! | H30: =SUMIFS(#REF!,#REF!,6,#REF!,2019,#REF!,"open") -> #REF! | I30: =SUMIFS(#REF!,#REF!,7,#REF!,2019,#REF!,"open") -> #REF! | J30: =SUMIFS(#REF!,#REF!,8,#REF!,2019,#REF!,"open") -> #REF! | K30: =SUMIFS(#REF!,#REF!,9,#REF!,2019,#REF!,"open") -> #REF! | L30: =SUMIFS(#REF!,#REF!,10,#REF!,2019,#REF!,"open") -> #REF! | M30: =SUMIFS(#REF!,#REF!,11,#REF!,2019,#REF!,"open") -> #REF! | N30: =SUMIFS(#REF!,#REF!,12,#REF!,2019,#REF!,"open") -> #REF! | O30: =SUM(C30:N30) -> #REF! | T30: =R30-Q30 -> 0
A31: Rolling Goal | C31: =SUMIFS(#REF!,#REF!,1,#REF!,2019,#REF!,"*",#REF!,"open") -> #REF! | D31: =SUMIFS(#REF!,#REF!,2,#REF!,2019,#REF!,"*",#REF!,"open") -> #REF! | E31: =SUMIFS(#REF!,#REF!,3,#REF!,2019,#REF!,"*",#REF!,"open") -> #REF! | F31: =SUMIFS(#REF!,#REF!,4,#REF!,2019,#REF!,"*",#REF!,"open") -> #REF! | G31: =SUMIFS(#REF!,#REF!,5,#REF!,2019,#REF!,"*",#REF!,"open") -> #REF! | H31: =SUMIFS(#REF!,#REF!,6,#REF!,2019,#REF!,"*",#REF!,"open") -> #REF! | I31: =SUMIFS(#REF!,#REF!,7,#REF!,2019,#REF!,"*",#REF!,"open") -> #REF! | J31: =SUMIFS(#REF!,#REF!,8,#REF!,2019,#REF!,"*",#REF!,"open") -> #REF! | K31: =SUMIFS(#REF!,#REF!,9,#REF!,2019,#REF!,"*",#REF!,"open") -> #REF! | L31: =SUMIFS(#REF!,#REF!,10,#REF!,2019,#REF!,"*",#REF!,"open") -> #REF! | M31: =SUMIFS(#REF!,#REF!,11,#REF!,2019,#REF!,"*",#REF!,"open") -> #REF! | N31: =SUMIFS(#REF!,#REF!,12,#REF!,2019,#REF!,"*",#REF!,"open") -> #REF! | O31: =SUM(C31:N31) -> #REF! | T31: =R31-Q31 -> 0
B32: Rolling GOAL Difference | C32: =C19-C26 -> 2253 | D32: =D19-D26+C32 -> 22371 | E32: =E19-E26+D32 -> 39297 | F32: =F19-F26+E32 -> -113128 | G32: =G19-G26+F32 -> -513128 | Q32: 6228 | R32: 9675 | S32: bunzl de mex | T32: =R32-Q32 -> 3447 | U32: =28/95 -> 0.29473684
A34: This green area does not roll into other areas. This is | B34: Project Revenue - Agreements | C34: =20000+95079 -> 115079 | D34: =20000+95079 -> 115079 | E34: =20000+95079 -> 115079 | O34: =SUM(C34:N34) -> 345237 | Q34: =SUM(Q27:Q33) -> 61242 | R34: =SUM(R27:R33) -> 94099
A35: a subset of AGREEMENT revenue. | B35: Project COGS Agreements (input) | C35: 68924 | D35: 68925 | E35: 68926 | O35: =SUM(C35:N35) -> 206775
A36: Breakdown reporting only | B36: Project Agreement Margin $ | C36: =C34-C35 -> 46155 | D36: =D34-D35 -> 46154 | E36: =E34-E35 -> 46153 | O36: =SUM(C36:N36) -> 138462 | Q36: =R34-Q34 -> 32857 | R36: =Q36/R34 -> 0.34917481
B37: Project Agreement Margin % | C37: =C36/C34 -> 0.40107231 | D37: =D36/D34 -> 0.40106362 | E37: =E36/E34 -> 0.40105493 | O37: =O36/O34 -> 0.40106362
B38: Agreement Revenue | C38: =C3 -> 294517 | D38: =D3 -> 287630 | E38: =E3 -> 296845 | F38: 197915 | G38: =G3 -> 0 | H38: =H3 -> 0 | I38: =I3 -> 0 | J38: =J3 -> 0 | K38: =K3 -> 0 | L38: =L3 -> 0 | M38: =M3 -> 0 | N38: =N3 -> 0 | O38: =SUM(C38:N38) -> 1076907
B39: Agreement COGS (input) | C39: 102260 | D39: 99927 | E39: 106236 | F39: 42127 | O39: =SUM(C39:N39) -> 350550
B40: Agreement Margin $ | C40: =C38-C39 -> 192257 | D40: =D38-D39 -> 187703 | E40: =E38-E39 -> 190609 | F40: =F38-F39 -> 155788 | G40: =G38-G39 -> 0 | H40: =H38-H39 -> 0 | I40: =I38-I39 -> 0 | J40: =J38-J39 -> 0 | ... N40: =N38-N39 -> 0 | O40: =SUM(C40:N40) -> 726357
B41: Agreement Margin % | C41: =C40/C38 -> 0.65278745 | D41: =D40/D38 -> 0.65258492 | E41: =E40/E38 -> 0.64211626 | F41: =F40/F38 -> 0.787146 | G41: =G40/G38 -> #DIV/0! | H41: =H40/H38 -> #DIV/0! | I41: =I40/I38 -> #DIV/0! | J41: =J40/J38 -> #DIV/0! | ... O41: =O40/O38 -> 0.67448443
B42: AGREEMENT MARGIN Reduction (previous month) | F42: =F40-E40 -> -34821
B43: Standard Revenue (w Misc & CMs) | C43: 107736 | D43: 132487 | E43: 120081 | F43: 49661 | O43: =SUM(C43:N43) -> 409965
...

Sheet Profitablility
E1: April | F1: 2026
E3: Agreement Revenue | F3: ='2026'!F3 -> 204317 | I3: =F3 -> 204317 | Q3: 1073
E4: Agreement COGS | F4: ='2026'!F39 -> 46377 | Q4: 5500
E5: Margin | F5: =F3-F4 -> 157940 | Q5: 4000
Q6: 4000
E7: Standard Revenue All | F7: ='2026'!F42 -> 101526 | I7: =F7 -> 101526
E8: Standard COGS NET | F8: ='2026'!F43 -> 67479
E9: Margin | F9: =F7-F8 -> 34047
E11: TOTAL Margin | F11: =F5+F9 -> 191987
E13: EXPENSES | F13: 205000 | K13: 131k in total payroll across all platforms | O13: 35k in expense | Q13: $165k total
E15: Co-Marketing Dollars - added | F15: =(12500+4000)/3 -> 5500 | I15: AvePoint and Barracuda | L15: 5.5k x 3 months
E17: NET Profitability | F17: =F11-F13+F15 -> -7513 | I17: Month to date
E19: Additional Cash Required | F19: 20000
E21: Total Cash NET | F21: =F17-F19 -> -27513 | I21: Month to date
E24: Project Additional Revenue | F24: 40000 | I24: Expected additional revenue based on YTD trend
E25: Margin expected - uses MTD trend | F25: ='2026'!F45 -> 0.33535252 | I25: MTD margin trend
E26: Net Expected Margin | F26: =F24*F25 -> 13414.101
E28: NET Profitability | F28: =F17+F26 -> 5901.1008 | I28: =F28/I32 -> 0.019294543
E29: NET CASH | F29: =F21+F26 -> -14098.899
I32: =I3+I7 -> 305843 | J32: Total Revenue MTD
I33: =I32*0.18 -> 55051.74 | J33: 0.18
I34: =F28 -> 5901.1008 | J34: =I34/I32 -> 0.019294543
I36: =I32+F24 -> 345843 | J36: Total Revenue Projected
I37: =I36*J37 -> 62251.74 | J37: 0.18

Sheet 2026
G1: 2026
A2: Forecast | C2: Jan | D2: Feb | E2: Mar | F2: Apr | G2: May | H2: Jun | I2: Jul | J2: Aug | K2: Sept | L2: Oct | M2: Nov | N2: Dec | O2: YTD Total
A3: Recurring Sales Invoiced | B3: Agreement | C3: 294517 | D3: 287630 | E3: 296845 | F3: 204317 | O3: =SUM(C3:N3) -> 1083309 | Q3: NOTES:
B4: New Agreement in Std | O4: =SUM(C4:N4) -> 0 | Q4: Agreement invoices that go out on the 8th of the month:
B5: ITMS | O5: =SUM(C5:N5) -> 0 | Q5: ARC - comprehensive services $84,000
B6: Licensing | O6: =SUM(F6:N6) -> 0 | Q6: Invoiced on 8th of month: BUNZL - de Mexico - invoiced this month for this month. Includes overages from last month. $17k
B7: Comprehensive Services | O7: =SUM(C7:N7) -> 0 | Q7: License Agreements = $38,000
B8: Other | O8: =SUM(C8:N8) -> 0
A10: New Sales Invoiced [INPUTS] | B10: Standard | C10: 106724 | D10: 147864 | E10: 126944 | F10: 101029 | O10: =SUM(C10:N10) -> 482561
B11: Miscellaneous - Invoiced | C11: 1642 | D11: 2385 | E11: 5357 | F11: 1295 | O11: =SUM(C11:N11) -> 10679
B12: Credit Memo - Invoiced | C12: -630 | D12: -17761 | E12: -12220 | F12: -5118 | O12: =SUM(C12:N12) -> -35729
E13: 5212
A14: Pending and Projected Sales | B14: Pending Project Milestones | G14: =10250+1800 -> 12050 | H14: =1125 -> 1125 | I14: 3600 | O14: =SUM(C14:N14) -> 16775 | T14: =R20-R21-R22 -> 66787
B15: Hubspot Pipeline at 40% | O15: =SUM(C15:N15) -> 0
B16: OPPS High Forecast (inputs)
B17: OPPS Low Forecast (inputs)
A19: Total | B19: Total Revenue | C19: =C3+C10+C11+C12 -> 402253 | D19: =D3+D10+D11+D12 -> 420118 | E19: =E3+E10+E11+E12 -> 416926 | F19: =F3+F10+F11+F12 -> 301523 | G19: =G3+G10+G11+G12 -> 0 | H19: =H3+H10+H11+H12 -> 0 | I19: =I3+I10+I11+I12 -> 0 | J19: =J3+J10+J11+J12 -> 0 | ... M19: =M3+M10+M11+M12 -> 0 | N19: =N3+N6+N10+N11+N12 -> 0 | O19: =SUM(C19:N19) -> 1540820 | R19: AGREEMENT | S19: Breakdown
B20: High | C20: =C3+C5+C6+C10+C11+C16+C12 -> 402253 | D20: =D3+D5+D6+D10+D11+D16+D12 -> 420118 | E20: =E3+E5+E6+E10+E11+E16+E12+E14 -> 416926 | F20: =F19+F16 -> 301523 | G20: =G3+G5+G6+G10+G11+G16+G12+G14 -> 12050 | H20: =H3+H5+H6+H10+H11+H16+H12+H14 -> 1125 | I20: =I3+I5+I6+I10+I11+I16+I12+I14 -> 3600 | J20: =J3+J5+J6+J10+J11+J16+J12+J14 -> 0 | K20: =K3+K5+K6+K7+K8+K10+K11+K12+K14+K16 -> 0 | L20: =L3+L5+L6+L7+L8+L10+L11+L12+L14+L16 -> 0 | M20: =M3+M5+M6+M7+M8+M10+M11+M12+M14+M16 -> 0 | N20: =N3+N5+N6+N7+N8+N10+N11+N12+N14+N16 -> 0 | R20: 310492 | S20: TOTAL
B21: Low | C21: =C3+C5+C6+C10+C11+C12+C17 -> 402253 | D21: =D3+D5+D6+D10+D11+D12+D17 -> 420118 | E21: =E3+E5+E6+E10+E11+E12+E17+E14 -> 416926 | F21: =F19+F17 -> 301523 | G21: =G3+G5+G6+G10+G11+G12+G17+G14 -> 12050 | H21: =H3+H5+H6+H10+H11+H12+H17+H14 -> 1125 | I21: =I3+I5+I6+I10+I11+I12+I17+I14 -> 3600 | J21: =J3+J5+J6+J10+J11+J12+J17+J14 -> 0 | K21: =K3+K5+K6+K7+K8+K10+K11+K12+K14+K17 -> 0 | L21: =L3+L5+L6+L7+L8+L10+L11+L12+L14+L17 -> 0 | M21: =M3+M5+M6+M7+M8+M10+M11+M12+M14+M17 -> 0 | N21: =N3+N5+N6+N7+N8+N10+N11+N12+N14+N17 -> 0 | R21: =84424+9675 -> 94099 | S21: Comp Services + Project (BUNZL de Mex)
A22: Gap (/mo) | B22: Revenue to Goal | C22: =C19-C26 -> 2253 | D22: =D19-D26 -> 20118 | E22: =E19-E26 -> 16926 | F22: =F19-F26 -> -98477 | G22: =G19-G26 -> -400000 | H22: =H19-H26 -> -400000 | I22: =I19-I26 -> -400000 | J22: =J19-J26 -> -400000 | ... N22: =N19-N26 -> -400001 | O22: =SUM(C22:N22) -> -3259181 | R22: 149606 | S22: Managed Services
R23: =R20-R21-R22 -> 66787 | S23: Licensing/Server (Agreement)
A24: Rolling Actual/Forecast | B24: Actual | C24: =C19 -> 402253 | D24: =C24+D19 -> 822371 | E24: =D24+E19 -> 1239297 | F24: =E24+F19 -> 1540820 | G24: =F24+G19 -> 1540820 | H24: =G24+H19 -> 1540820 | I24: =H24+I19 -> 1540820 | J24: =I24+J19 -> 1540820 | K24: =J24+K19 -> 1540820 | ... N24: =M24+N19 -> 1540820 | O24: =N24 -> 1540820
B25: Actual ROLLING | C25: =C19 -> 402253 | D25: =C25+D19 -> 822371 | E25: =D25+E19 -> 1239297 | F25: =E25+F19 -> 1540820 | G25: =F25+G19 -> 1540820 | H25: =G25+H19 -> 1540820 | I25: =H25+I19 -> 1540820 | J25: =I25+J19 -> 1540820 | K25: =J25+K19 -> 1540820 | ... N25: =M25+N19 -> 1540820
A26: Monthly Goal | B26: Revenue GOAL | C26: 400000 | D26: 400000 | E26: 400000 | F26: 400000 | G26: 400000 | H26: 400000 | I26: 400000 | J26: 400000 | K26: 400000 | L26: 400000 | M26: 400000 | N26: 400001 | O26: =SUM(C26:N26) -> 4800001 | Q26: cogs | R26: rev
B27: Rolling GOAL | C27: =C26 -> 400000 | D27: =C27+D26 -> 800000 | E27: =D27+E26 -> 1200000 | F27: =E27+F26 -> 1600000 | G27: =F27+G26 -> 2000000 | H27: =G27+H26 -> 2400000 | I27: =H27+I26 -> 2800000 | J27: =I27+J26 -> 3200000 | K27: =J27+K26 -> 3600000 | ... N27: =M27+N26 -> 4800001 | O27: =N27 -> 4800001 | Q27: 55014 | R27: 84424 | S27: arc | T27: =R27-Q27 -> 29410 | U27: =T27/R27 -> 0.34836066
A28: Rolling Goal | C28: =C24-C27 -> 2253 | D28: =D24-D27 -> 22371 | E28: =E24-E27 -> 39297 | F28: =F24-F27 -> -59180 | G28: =G24-G27 -> -459180 | H28: =H24-H27 -> -859180 | I28: =I24-I27 -> -1259180 | J28: =J24-J27 -> -1659180 | ... N28: =N24-N27 -> -3259181 | O28: =N28 -> -3259181 | T28: =R28-Q28 -> 0
A29: Rolling Goal | C29: Jan | D29: Feb | E29: Mar | F29: Apr | G29: May | H29: Jun | I29: Jul | J29: Aug | K29: Sept | L29: Oct | M29: Nov | N29: Dec | O29: 2019 | T29: =R29-Q29 -> 0
A30: Rolling Goal | C30: =SUMIFS(#REF!,#REF!,1,#REF!,2019,#REF!,"open") -> #REF! | D30: =SUMIFS(#REF!,#REF!,2,#REF!,2019,#REF!,"open") -> #REF! | E30: =SUMIFS(#REF!,#REF!,3,#REF!,2019,#REF!,"open") -> #REF! | F30: =SUMIFS(#REF!,#REF!,4,#REF!,2019,#REF!,"open") -> #REF! | G30: =SUMIFS(#REF!,#REF!,5,#REF!,2019,#REF!,"open") -> #REF! | H30: =SUMIFS(#REF!,#REF!,6,#REF!,2019,#REF!,"open") -> #REF! | I30: =SUMIFS(#REF!,#REF!,7,#REF!,2019,#REF!,"open") -> #REF! | J30: =SUMIFS(#REF!,#REF!,8,#REF!,2019,#REF!,"open") -> #REF! | K30: =SUMIFS(#REF!,#REF!,9,#REF!,2019,#REF!,"open") -> #REF! | L30: =SUMIFS(#REF!,#REF!,10,#REF!,2019,#REF!,"open") -> #REF! | M30: =SUMIFS(#REF!,#REF!,11,#REF!,2019,#REF!,"open") -> #REF! | N30: =SUMIFS(#REF!,#REF!,12,#REF!,2019,#REF!,"open") -> #REF! | O30: =SUM(C30:N30) -> #REF! | T30: =R30-Q30 -> 0
A31: Rolling Goal | C31: =SUMIFS(#REF!,#REF!,1,#REF!,2019,#REF!,"*",#REF!,"open") -> #REF! | D31: =SUMIFS(#REF!,#REF!,2,#REF!,2019,#REF!,"*",#REF!,"open") -> #REF! | E31: =SUMIFS(#REF!,#REF!,3,#REF!,2019,#REF!,"*",#REF!,"open") -> #REF! | F31: =SUMIFS(#REF!,#REF!,4,#REF!,2019,#REF!,"*",#REF!,"open") -> #REF! | G31: =SUMIFS(#REF!,#REF!,5,#REF!,2019,#REF!,"*",#REF!,"open") -> #REF! | H31: =SUMIFS(#REF!,#REF!,6,#REF!,2019,#REF!,"*",#REF!,"open") -> #REF! | I31: =SUMIFS(#REF!,#REF!,7,#REF!,2019,#REF!,"*",#REF!,"open") -> #REF! | J31: =SUMIFS(#REF!,#REF!,8,#REF!,2019,#REF!,"*",#REF!,"open") -> #REF! | K31: =SUMIFS(#REF!,#REF!,9,#REF!,2019,#REF!,"*",#REF!,"open") -> #REF! | L31: =SUMIFS(#REF!,#REF!,10,#REF!,2019,#REF!,"*",#REF!,"open") -> #REF! | M31: =SUMIFS(#REF!,#REF!,11,#REF!,2019,#REF!,"*",#REF!,"open") -> #REF! | N31: =SUMIFS(#REF!,#REF!,12,#REF!,2019,#REF!,"*",#REF!,"open") -> #REF! | O31: =SUM(C31:N31) -> #REF! | T31: =R31-Q31 -> 0
B32: Rolling GOAL Difference | C32: =C19-C26 -> 2253 | D32: =D19-D26+C32 -> 22371 | E32: =E19-E26+D32 -> 39297 | F32: =F19-F26+E32 -> -59180 | G32: =G19-G26+F32 -> -459180 | Q32: 6228 | R32: 9675 | S32: bunzl de mex | T32: =R32-Q32 -> 3447 | U32: =28/95 -> 0.29473684
A34: This green area does not roll into other areas. This is | B34: Project Revenue - Agreements | C34: =20000+95079 -> 115079 | D34: =20000+95079 -> 115079 | E34: =20000+95079 -> 115079 | O34: =SUM(C34:N34) -> 345237 | Q34: =SUM(Q27:Q33) -> 61242 | R34: =SUM(R27:R33) -> 94099
A35: a subset of AGREEMENT revenue. | B35: Project COGS Agreements (input) | C35: 68924 | D35: 68925 | E35: 68926 | O35: =SUM(C35:N35) -> 206775
A36: Breakdown reporting only | B36: Project Agreement Margin $ | C36: =C34-C35 -> 46155 | D36: =D34-D35 -> 46154 | E36: =E34-E35 -> 46153 | O36: =SUM(C36:N36) -> 138462 | Q36: =R34-Q34 -> 32857 | R36: =Q36/R34 -> 0.34917481
B37: Project Agreement Margin % | C37: =C36/C34 -> 0.40107231 | D37: =D36/D34 -> 0.40106362 | E37: =E36/E34 -> 0.40105493 | O37: =O36/O34 -> 0.40106362
B38: Agreement Revenue | C38: =C3 -> 294517 | D38: =D3 -> 287630 | E38: =E3 -> 296845 | F38: =F3 -> 204317 | G38: =G3 -> 0 | H38: =H3 -> 0 | I38: =I3 -> 0 | J38: =J3 -> 0 | ... N38: =N3 -> 0 | O38: =SUM(C38:N38) -> 1083309
B39: Agreement COGS (input) | C39: 102260 | D39: 99927 | E39: 106236 | F39: 46377 | O39: =SUM(C39:N39) -> 354800
B40: Agreement Margin $ | C40: =C38-C39 -> 192257 | D40: =D38-D39 -> 187703 | E40: =E38-E39 -> 190609 | F40: =F38-F39 -> 157940 | G40: =G38-G39 -> 0 | H40: =H38-H39 -> 0 | I40: =I38-I39 -> 0 | J40: =J38-J39 -> 0 | ... N40: =N38-N39 -> 0 | O40: =SUM(C40:N40) -> 728509
B41: Agreement Margin % | C41: =C40/C38 -> 0.65278745 | D41: =D40/D38 -> 0.65258492 | E41: =E40/E38 -> 0.64211626 | F41: =F40/F38 -> 0.77301448 | G41: =G40/G38 -> #DIV/0! | H41: =H40/H38 -> #DIV/0! | I41: =I40/I38 -> #DIV/0! | J41: =J40/J38 -> #DIV/0! | ... O41: =O40/O38 -> 0.67248495
B42: Standard Revenue (w Misc & CMs) | C42: 107736 | D42: 132487 | E42: 120081 | F42: 101526 | O42: =SUM(C42:N42) -> 461830
B43: Standard Misc COGS (input) | C43: 67536 | D43: 83944 | E43: 76229 | F43: 67479 | O43: =SUM(C43:N43) -> 295188
...

Sheet 2025
G1: 2025
A2: Forecast | C2: Jan | D2: Feb | E2: Mar | F2: Apr | G2: May | H2: Jun | I2: Jul | J2: Aug | K2: Sept | L2: Oct | M2: Nov | N2: Dec | O2: YTD Total
A3: Recurring Sales Invoiced | B3: Agreement | C3: 322280 | D3: 321976 | E3: 328979 | F3: 382362 | G3: 381216 | H3: 364130 | I3: 316503 | J3: 320352 | K3: 316248 | L3: 310492 | M3: 315280 | N3: 318600 | O3: =SUM(C3:N3) -> 3998418 | Q3: NOTES:
B4: New Agreement in Std | O4: =SUM(C4:N4) -> 0 | Q4: Agreement invoices that are delayed until 8th of the month:
B5: ITMS | O5: =SUM(C5:N5) -> 0 | Q5: ARC - comprehensive services $84,000
B6: Licensing | O6: =SUM(F6:N6) -> 0 | Q6: Invoiced on 8th of month: BUNZL - de Mexico - invoiced this month for this month. Includes overages from last month. $9500
B7: Comprehensive Services | O7: =SUM(C7:N7) -> 0 | Q7: License Agreements = $38,000
B8: Other | O8: =SUM(C8:N8) -> 0
A10: New Sales Invoiced [INPUTS] | B10: Standard and Misc - Invoiced | C10: 40401 | D10: 103232 | E10: 59881 | F10: 142704 | G10: 144085 | H10: 62777 | I10: 58928 | J10: 244650 | K10: 73181 | L10: 108546 | M10: 90268 | N10: 111861 | O10: =SUM(C10:N10) -> 1240514
B11: Miscellaneous - Invoiced | N11: 4418 | O11: =SUM(C11:N11) -> 4418
B12: Credit Memo - Invoiced | N12: -16530 | O12: =SUM(C12:N12) -> -16530
P13: TOTAL
A14: Pending and Projected Sales | B14: Pending Project Milestones | N14: 18000 | O14: =SUM(C14:N14) -> 18000 | P14: 49235 | T14: =R20-R21-R22 -> 66787
B15: Hubspot Pipeline at 40% | O15: =SUM(C15:N15) -> 0
B16: OPPS High Forecast (inputs)
B17: OPPS Low Forecast (inputs)
A19: Total | B19: Total Revenue | C19: =C3+C6+C10 -> 362681 | D19: =D3+D6+D10 -> 425208 | E19: =E3+E6+E10 -> 388860 | F19: =F3+F6+F10 -> 525066 | G19: =G3+G6+G10 -> 525301 | H19: =H3+H6+H10 -> 426907 | I19: =I3+I6+I10 -> 375431 | J19: =J3+J6+J10 -> 565002 | ... M19: =M3+M6+M10 -> 405548 | N19: =N3+N6+N10+N11+N12 -> 418349 | O19: =SUM(C19:N19) -> 5226820 | R19: AGREEMENT | S19: Breakdown
B20: High | C20: =C3+C5+C6+C10+C11+C16+C12 -> 362681 | D20: =D3+D5+D6+D10+D11+D16+D12 -> 425208 | E20: =E3+E5+E6+E10+E11+E16+E12+E14 -> 388860 | F20: =F19+F16 -> 525066 | G20: =G3+G5+G6+G10+G11+G16+G12+G14 -> 525301 | H20: =H3+H5+H6+H10+H11+H16+H12+H14 -> 426907 | I20: =I3+I5+I6+I10+I11+I16+I12+I14 -> 375431 | J20: =J3+J5+J6+J10+J11+J16+J12+J14 -> 565002 | K20: =K3+K5+K6+K7+K8+K10+K11+K12+K14+K16 -> 389429 | L20: =L3+L5+L6+L7+L8+L10+L11+L12+L14+L16 -> 419038 | M20: =M3+M5+M6+M7+M8+M10+M11+M12+M14+M16 -> 405548 | N20: =N3+N5+N6+N7+N8+N10+N11+N12+N14+N16 -> 436349 | R20: 310492 | S20: TOTAL
B21: Low | C21: =C3+C5+C6+C10+C11+C12+C17 -> 362681 | D21: =D3+D5+D6+D10+D11+D12+D17 -> 425208 | E21: =E3+E5+E6+E10+E11+E12+E17+E14 -> 388860 | F21: =F19+F17 -> 525066 | G21: =G3+G5+G6+G10+G11+G12+G17+G14 -> 525301 | H21: =H3+H5+H6+H10+H11+H12+H17+H14 -> 426907 | I21: =I3+I5+I6+I10+I11+I12+I17+I14 -> 375431 | J21: =J3+J5+J6+J10+J11+J12+J17+J14 -> 565002 | K21: =K3+K5+K6+K7+K8+K10+K11+K12+K14+K17 -> 389429 | L21: =L3+L5+L6+L7+L8+L10+L11+L12+L14+L17 -> 419038 | M21: =M3+M5+M6+M7+M8+M10+M11+M12+M14+M17 -> 405548 | N21: =N3+N5+N6+N7+N8+N10+N11+N12+N14+N17 -> 436349 | R21: =84424+9675 -> 94099 | S21: Comp Services + Project (BUNZL de Mex)
A22: Gap (/mo) | B22: Revenue to Goal | C22: =C19-C26 -> -37319 | D22: =D19-D26 -> 25208 | E22: =E19-E26 -> -11140 | F22: =F19-F26 -> 125066 | G22: =G19-G26 -> 125301 | H22: =H19-H26 -> 26907 | I22: =I19-I26 -> -24569 | J22: =J19-J26 -> 165002 | ... N22: =N19-N26 -> 18348 | O22: =SUM(C22:N22) -> 426819 | R22: 149606 | S22: Managed Services
R23: =R20-R21-R22 -> 66787 | S23: Licensing/Server (Agreement)
A24: Rolling Actual/Forecast | B24: Actual | C24: =C19 -> 362681 | D24: =C24+D19 -> 787889 | E24: =D24+E19 -> 1176749 | F24: =E24+F19 -> 1701815 | G24: =F24+G19 -> 2227116 | H24: =G24+H19 -> 2654023 | I24: =H24+I19 -> 3029454 | J24: =I24+J19 -> 3594456 | K24: =J24+K19 -> 3983885 | ... N24: =M24+N19 -> 5226820 | O24: =N24 -> 5226820
B25: Actual ROLLING | C25: =C19 -> 362681 | D25: =C25+D19 -> 787889 | E25: =D25+E19 -> 1176749 | F25: =E25+F19 -> 1701815 | G25: =F25+G19 -> 2227116 | H25: =G25+H19 -> 2654023 | I25: =H25+I19 -> 3029454 | J25: =I25+J19 -> 3594456 | K25: =J25+K19 -> 3983885 | ... N25: =M25+N19 -> 5226820
A26: Monthly Goal | B26: Revenue GOAL | C26: 400000 | D26: 400000 | E26: 400000 | F26: 400000 | G26: 400000 | H26: 400000 | I26: 400000 | J26: 400000 | K26: 400000 | L26: 400000 | M26: 400000 | N26: 400001 | O26: =SUM(C26:N26) -> 4800001 | Q26: cogs | R26: rev
B27: Rolling GOAL | C27: =C26 -> 400000 | D27: =C27+D26 -> 800000 | E27: =D27+E26 -> 1200000 | F27: =E27+F26 -> 1600000 | G27: =F27+G26 -> 2000000 | H27: =G27+H26 -> 2400000 | I27: =H27+I26 -> 2800000 | J27: =I27+J26 -> 3200000 | K27: =J27+K26 -> 3600000 | ... N27: =M27+N26 -> 4800001 | O27: =N27 -> 4800001 | Q27: 55014 | R27: 84424 | S27: arc | T27: =R27-Q27 -> 29410 | U27: =T27/R27 -> 0.34836066
A28: Rolling Goal | C28: =C24-C27 -> -37319 | D28: =D24-D27 -> -12111 | E28: =E24-E27 -> -23251 | F28: =F24-F27 -> 101815 | G28: =G24-G27 -> 227116 | H28: =H24-H27 -> 254023 | I28: =I24-I27 -> 229454 | J28: =J24-J27 -> 394456 | ... N28: =N24-N27 -> 426819 | O28: =N28 -> 426819 | T28: =R28-Q28 -> 0
A29: Rolling Goal | C29: Jan | D29: Feb | E29: Mar | F29: Apr | G29: May | H29: Jun | I29: Jul | J29: Aug | K29: Sept | L29: Oct | M29: Nov | N29: Dec | O29: 2019 | T29: =R29-Q29 -> 0
A30: Rolling Goal | C30: =SUMIFS(#REF!,#REF!,1,#REF!,2019,#REF!,"open") -> #REF! | D30: =SUMIFS(#REF!,#REF!,2,#REF!,2019,#REF!,"open") -> #REF! | E30: =SUMIFS(#REF!,#REF!,3,#REF!,2019,#REF!,"open") -> #REF! | F30: =SUMIFS(#REF!,#REF!,4,#REF!,2019,#REF!,"open") -> #REF! | G30: =SUMIFS(#REF!,#REF!,5,#REF!,2019,#REF!,"open") -> #REF! | H30: =SUMIFS(#REF!,#REF!,6,#REF!,2019,#REF!,"open") -> #REF! | I30: =SUMIFS(#REF!,#REF!,7,#REF!,2019,#REF!,"open") -> #REF! | J30: =SUMIFS(#REF!,#REF!,8,#REF!,2019,#REF!,"open") -> #REF! | K30: =SUMIFS(#REF!,#REF!,9,#REF!,2019,#REF!,"open") -> #REF! | L30: =SUMIFS(#REF!,#REF!,10,#REF!,2019,#REF!,"open") -> #REF! | M30: =SUMIFS(#REF!,#REF!,11,#REF!,2019,#REF!,"open") -> #REF! | N30: =SUMIFS(#REF!,#REF!,12,#REF!,2019,#REF!,"open") -> #REF! | O30: =SUM(C30:N30) -> #REF! | T30: =R30-Q30 -> 0
A31: Rolling Goal | C31: =SUMIFS(#REF!,#REF!,1,#REF!,2019,#REF!,"*",#REF!,"open") -> #REF! | D31: =SUMIFS(#REF!,#REF!,2,#REF!,2019,#REF!,"*",#REF!,"open") -> #REF! | E31: =SUMIFS(#REF!,#REF!,3,#REF!,2019,#REF!,"*",#REF!,"open") -> #REF! | F31: =SUMIFS(#REF!,#REF!,4,#REF!,2019,#REF!,"*",#REF!,"open") -> #REF! | G31: =SUMIFS(#REF!,#REF!,5,#REF!,2019,#REF!,"*",#REF!,"open") -> #REF! | H31: =SUMIFS(#REF!,#REF!,6,#REF!,2019,#REF!,"*",#REF!,"open") -> #REF! | I31: =SUMIFS(#REF!,#REF!,7,#REF!,2019,#REF!,"*",#REF!,"open") -> #REF! | J31: =SUMIFS(#REF!,#REF!,8,#REF!,2019,#REF!,"*",#REF!,"open") -> #REF! | K31: =SUMIFS(#REF!,#REF!,9,#REF!,2019,#REF!,"*",#REF!,"open") -> #REF! | L31: =SUMIFS(#REF!,#REF!,10,#REF!,2019,#REF!,"*",#REF!,"open") -> #REF! | M31: =SUMIFS(#REF!,#REF!,11,#REF!,2019,#REF!,"*",#REF!,"open") -> #REF! | N31: =SUMIFS(#REF!,#REF!,12,#REF!,2019,#REF!,"*",#REF!,"open") -> #REF! | O31: =SUM(C31:N31) -> #REF! | T31: =R31-Q31 -> 0
B32: Rolling GOAL Difference | C32: =C19-C26 -> -37319 | D32: =D19-D26+C32 -> -12111 | E32: =E19-E26+D32 -> -23251 | F32: =F19-F26+E32 -> 101815 | G32: =G19-G26+F32 -> 227116 | Q32: 6228 | R32: 9675 | S32: bunzl de mex | T32: =R32-Q32 -> 3447 | U32: =28/95 -> 0.29473684
A34: This green area does not roll into other areas. This is | B34: Project Revenue - Agreements | C34: =20000+95079 -> 115079 | D34: =20000+95079 -> 115079 | E34: =20000+95079 -> 115079 | O34: =SUM(C34:N34) -> 345237 | Q34: =SUM(Q27:Q33) -> 61242 | R34: =SUM(R27:R33) -> 94099
A35: a subset of AGREEMENT revenue. | B35: Project COGS Agreements (input) | C35: 68924 | D35: 68925 | E35: 68926 | O35: =SUM(C35:N35) -> 206775
A36: Breakdown reporting only | B36: Project Agreement Margin $ | C36: =C34-C35 -> 46155 | D36: =D34-D35 -> 46154 | E36: =E34-E35 -> 46153 | O36: =SUM(C36:N36) -> 138462 | Q36: =R34-Q34 -> 32857 | R36: =Q36/R34 -> 0.34917481
B37: Project Agreement Margin % | C37: =C36/C34 -> 0.40107231 | D37: =D36/D34 -> 0.40106362 | E37: =E36/E34 -> 0.40105493 | O37: =O36/O34 -> 0.40106362
B38: Agreement Revenue | C38: =C3 -> 322280 | D38: =D3 -> 321976 | E38: =E3 -> 328979 | F38: =F3 -> 382362 | G38: =G3 -> 381216 | H38: =H3 -> 364130 | I38: =I3 -> 316503 | J38: =J3 -> 320352 | ... N38: =N3 -> 318600 | O38: =SUM(C38:N38) -> 3998418
B39: Agreement COGS (input) | C39: 102260 | D39: 99047 | E39: 118852 | F39: 145278 | G39: 142903 | H39: 135588 | I39: 110189 | J39: 111801 | K39: 110187 | L39: 107556 | M39: 110176 | N39: 110177 | O39: =SUM(C39:N39) -> 1404014
B40: Agreement Margin $ | C40: =C38-C39 -> 220020 | D40: =D38-D39 -> 222929 | E40: =E38-E39 -> 210127 | F40: =F38-F39 -> 237084 | G40: =G38-G39 -> 238313 | H40: =H38-H39 -> 228542 | I40: =I38-I39 -> 206314 | J40: =J38-J39 -> 208551 | ... N40: =N38-N39 -> 208423 | O40: =SUM(C40:N40) -> 2594404
B41: Agreement Margin % | C41: =C40/C38 -> 0.68269827 | D41: =D40/D38 -> 0.69237769 | E41: =E40/E38 -> 0.63872466 | F41: =F40/F38 -> 0.62005116 | G41: =G40/G38 -> 0.62513903 | H41: =H40/H38 -> 0.62763848 | I41: =I40/I38 -> 0.6518548 | J41: =J40/J38 -> 0.65100577 | ... O41: =O40/O38 -> 0.64885762
B42: Standard Revenue (w Misc & CMs) | C42: =C10 -> 40401 | D42: =D10 -> 103232 | E42: =E10 -> 59881 | F42: =F10 -> 142704 | G42: =G10 -> 144085 | H42: =H10 -> 62777 | I42: =I10 -> 58928 | J42: =J10 -> 244650 | ... M42: =M10 -> 90268 | N42: 99748 | O42: =SUM(C42:N42) -> 1228401
B43: Standard Misc COGS (input) | C43: 28221 | D43: 69474 | E43: 35161 | F43: 83376 | G43: 99661 | H43: 40425 | I43: 39040 | J43: 193722 | K43: 45707 | L43: 62784 | M43: 59227 | N43: 58463 | O43: =SUM(C43:N43) -> 815261
...

Sheet 2024
A1: Today: | B1: =TODAY() -> 46147 | G1: 2024
A2: Forecast | C2: Jan | D2: Feb | E2: Mar | F2: Apr | G2: May | H2: Jun | I2: Jul | J2: Aug | K2: Sept | L2: Oct | M2: Nov | N2: Dec | O2: YTD Total
A3: Recurring Sales Invoiced | B3: Agreement | C3: 348558 | D3: 347041 | E3: 343646 | F3: 360526 | G3: 360034 | H3: 357860 | I3: 356659 | J3: 355372 | K3: 359721 | L3: 368176 | M3: 368348 | N3: 373130 | O3: =SUM(C3:N3) -> 4299071 | Q3: NOTES:
B4: New Agreement in Std | O4: =SUM(C4:N4) -> 0 | Q4: Agreement invoices that are delayed until 8th of the month:
B5: ITMS | O5: =SUM(C5:N5) -> 0 | Q5: Amiri - emailed to client with date created, then date changed to first of next month (MS invoices)
B6: Licensing | O6: =SUM(F6:N6) -> 0 | Q6: BUNZL - path to the cloud invoiced on 8th or so of every month
B7: Comprehensive Services | O7: =SUM(C7:N7) -> 0 | Q7: License Agreement invoices (24k ish) completed on same day, first ish of the month. Once synnex auto updates.
B8: Other | O8: =SUM(C8:N8) -> 0
A10: New Sales Invoiced [INPUTS] | B10: Standard and Misc - Invoiced | C10: 142362 | D10: 229434 | E10: 86779 | F10: 77612 | G10: 126216 | H10: 56715 | I10: 95800 | J10: 81425 | K10: 133285 | L10: 151749 | M10: 54579 | N10: 65199 | O10: =SUM(C10:N10) -> 1301155
B11: Miscellaneous - Invoiced | O11: =SUM(C11:N11) -> 0
B12: Credit Memo - Invoiced | O12: =SUM(C12:N12) -> 0
Q13: revenue | R13: 387307
A14: Pending and Projected Sales | B14: Pending Project Milestones | N14: =3600+7200 -> 10800 | O14: =SUM(C14:N14) -> 10800 | P14: move to 1/31/25 | Q14: margin | R14: 175674 | S14: =R14/R13 -> 0.45357817
B15: Hubspot Pipeline at 40% | O15: =SUM(C15:N15) -> 0 | R15: =R14/12 -> 14639.5
B16: OPPS High Forecast (inputs)
B17: OPPS Low Forecast (inputs)
A19: Total | B19: Total Revenue | C19: =C3+C6+C10 -> 490920 | D19: =D3+D6+D10 -> 576475 | E19: =E3+E6+E10 -> 430425 | F19: =F3+F6+F10 -> 438138 | G19: =G3+G6+G10 -> 486250 | H19: =H3+H6+H10 -> 414575 | I19: =I3+I6+I10 -> 452459 | J19: =J3+J6+J10 -> 436797 | ... N19: =N3+N6+N10 -> 438329 | O19: =SUM(C19:N19) -> 5600226 | R19: AGREEMENT | S19: Breakdown
B20: High | C20: =C3+C5+C6+C10+C11+C16+C12 -> 490920 | D20: =D3+D5+D6+D10+D11+D16+D12 -> 576475 | E20: =E3+E5+E6+E10+E11+E16+E12+E14 -> 430425 | F20: =F19+F16 -> 438138 | G20: =G3+G5+G6+G10+G11+G16+G12+G14 -> 486250 | H20: =H3+H5+H6+H10+H11+H16+H12+H14 -> 414575 | I20: =I3+I5+I6+I10+I11+I16+I12+I14 -> 452459 | J20: =J3+J5+J6+J10+J11+J16+J12+J14 -> 436797 | K20: =K3+K5+K6+K7+K8+K10+K11+K12+K14+K16 -> 493006 | L20: =L3+L5+L6+L7+L8+L10+L11+L12+L14+L16 -> 519925 | M20: =M3+M5+M6+M7+M8+M10+M11+M12+M14+M16 -> 422927 | N20: =N3+N5+N6+N7+N8+N10+N11+N12+N14+N16 -> 449129 | R20: 368176 | S20: TOTAL
B21: Low | C21: =C3+C5+C6+C10+C11+C12+C17 -> 490920 | D21: =D3+D5+D6+D10+D11+D12+D17 -> 576475 | E21: =E3+E5+E6+E10+E11+E12+E17+E14 -> 430425 | F21: =F19+F17 -> 438138 | G21: =G3+G5+G6+G10+G11+G12+G17+G14 -> 486250 | H21: =H3+H5+H6+H10+H11+H12+H17+H14 -> 414575 | I21: =I3+I5+I6+I10+I11+I12+I17+I14 -> 452459 | J21: =J3+J5+J6+J10+J11+J12+J17+J14 -> 436797 | K21: =K3+K5+K6+K7+K8+K10+K11+K12+K14+K17 -> 493006 | L21: =L3+L5+L6+L7+L8+L10+L11+L12+L14+L17 -> 519925 | M21: =M3+M5+M6+M7+M8+M10+M11+M12+M14+M17 -> 422927 | N21: =N3+N5+N6+N7+N8+N10+N11+N12+N14+N17 -> 449129 | R21: 135079 | S21: Project
A22: Gap (/mo) | B22: Revenue to Goal | C22: =C19-C26 -> 40920 | D22: =D19-D26 -> 126475 | E22: C | F22: =F19-F26 -> -36862 | G22: =G19-G26 -> 11250 | H22: =H19-H26 -> -60425 | I22: =I19-I26 -> -22541 | J22: =J19-J26 -> -38203 | K22: =K19-K26 -> 18006 | O22: =SUM(C22:N22) -> 38620 | R22: 175685 | S22: Managed Services
R23: =R20-R21-R22 -> 57412 | S23: Licensing (Agreement)
A24: Rolling Actual/Forecast | B24: Actual | C24: =C19 -> 490920 | D24: =C24+D19 -> 1067395 | E24: =D24+E19 -> 1497820 | F24: =E24+F19 -> 1935958 | G24: =F24+G19 -> 2422208 | H24: =G24+H19 -> 2836783 | I24: =H24+I19 -> 3289242 | J24: =I24+J19 -> 3726039 | K24: =J24+K19 -> 4219045 | ... N24: =M24+N19 -> 5600226 | O24: =N24 -> 5600226
B25: Actual ROLLING | C25: =C19 -> 490920 | D25: =C25+D19 -> 1067395 | E25: =D25+E19 -> 1497820 | F25: =E25+F19 -> 1935958 | G25: =F25+G19 -> 2422208 | H25: =G25+H19 -> 2836783 | I25: =H25+I19 -> 3289242 | J25: =I25+J19 -> 3726039 | K25: =J25+K19 -> 4219045 | ... N25: =M25+N19 -> 5600226
A26: Monthly Goal | B26: Revenue GOAL | C26: 450000 | D26: 450000 | E26: 450000 | F26: 475000 | G26: 475000 | H26: 475000 | I26: 475000 | J26: 475000 | K26: 475000 | L26: 475000 | M26: 475000 | N26: 475000 | O26: =SUM(C26:N26) -> 5625000 | Q26: cogs | R26: rev
B27: Rolling GOAL | C27: =C26 -> 450000 | D27: =C27+D26 -> 900000 | E27: =D27+E26 -> 1350000 | F27: =E27+F26 -> 1825000 | G27: =F27+G26 -> 2300000 | H27: =G27+H26 -> 2775000 | I27: =H27+I26 -> 3250000 | J27: =I27+J26 -> 3725000 | K27: =J27+K26 -> 4200000 | ... N27: =M27+N26 -> 5625000 | O27: =N27 -> 5625000 | Q27: 58924 | R27: 95079 | S27: arc | T27: =R27-Q27 -> 36155 | U27: =T27/R27 -> 0.38026273
A28: Rolling Goal | C28: =C24-C27 -> 40920 | D28: =D24-D27 -> 167395 | E28: =E24-E27 -> 147820 | F28: =F24-F27 -> 110958 | G28: =G24-G27 -> 122208 | H28: =H24-H27 -> 61783 | I28: =I24-I27 -> 39242 | J28: =J24-J27 -> 1039 | ... N28: =N24-N27 -> -24774 | O28: =N28 -> -24774
A29: Rolling Goal | C29: Jan | D29: Feb | E29: Mar | F29: Apr | G29: May | H29: Jun | I29: Jul | J29: Aug | K29: Sept | L29: Oct | M29: Nov | N29: Dec | O29: 2019
A30: Rolling Goal | C30: =SUMIFS(#REF!,#REF!,1,#REF!,2019,#REF!,"open") -> #REF! | D30: =SUMIFS(#REF!,#REF!,2,#REF!,2019,#REF!,"open") -> #REF! | E30: =SUMIFS(#REF!,#REF!,3,#REF!,2019,#REF!,"open") -> #REF! | F30: =SUMIFS(#REF!,#REF!,4,#REF!,2019,#REF!,"open") -> #REF! | G30: =SUMIFS(#REF!,#REF!,5,#REF!,2019,#REF!,"open") -> #REF! | H30: =SUMIFS(#REF!,#REF!,6,#REF!,2019,#REF!,"open") -> #REF! | I30: =SUMIFS(#REF!,#REF!,7,#REF!,2019,#REF!,"open") -> #REF! | J30: =SUMIFS(#REF!,#REF!,8,#REF!,2019,#REF!,"open") -> #REF! | K30: =SUMIFS(#REF!,#REF!,9,#REF!,2019,#REF!,"open") -> #REF! | L30: =SUMIFS(#REF!,#REF!,10,#REF!,2019,#REF!,"open") -> #REF! | M30: =SUMIFS(#REF!,#REF!,11,#REF!,2019,#REF!,"open") -> #REF! | N30: =SUMIFS(#REF!,#REF!,12,#REF!,2019,#REF!,"open") -> #REF! | O30: =SUM(C30:N30) -> #REF!
A31: Rolling Goal | C31: =SUMIFS(#REF!,#REF!,1,#REF!,2019,#REF!,"*",#REF!,"open") -> #REF! | D31: =SUMIFS(#REF!,#REF!,2,#REF!,2019,#REF!,"*",#REF!,"open") -> #REF! | E31: =SUMIFS(#REF!,#REF!,3,#REF!,2019,#REF!,"*",#REF!,"open") -> #REF! | F31: =SUMIFS(#REF!,#REF!,4,#REF!,2019,#REF!,"*",#REF!,"open") -> #REF! | G31: =SUMIFS(#REF!,#REF!,5,#REF!,2019,#REF!,"*",#REF!,"open") -> #REF! | H31: =SUMIFS(#REF!,#REF!,6,#REF!,2019,#REF!,"*",#REF!,"open") -> #REF! | I31: =SUMIFS(#REF!,#REF!,7,#REF!,2019,#REF!,"*",#REF!,"open") -> #REF! | J31: =SUMIFS(#REF!,#REF!,8,#REF!,2019,#REF!,"*",#REF!,"open") -> #REF! | K31: =SUMIFS(#REF!,#REF!,9,#REF!,2019,#REF!,"*",#REF!,"open") -> #REF! | L31: =SUMIFS(#REF!,#REF!,10,#REF!,2019,#REF!,"*",#REF!,"open") -> #REF! | M31: =SUMIFS(#REF!,#REF!,11,#REF!,2019,#REF!,"*",#REF!,"open") -> #REF! | N31: =SUMIFS(#REF!,#REF!,12,#REF!,2019,#REF!,"*",#REF!,"open") -> #REF! | O31: =SUM(C31:N31) -> #REF!
B32: Rolling GOAL Difference | C32: =C19-C26 -> 40920 | D32: =D19-D26+C32 -> 167395 | E32: =E19-E26+D32 -> 147820 | F32: =F19-F26+E32 -> 110958 | G32: =G19-G26+F32 -> 122208 | Q32: 20000 | R32: 40000 | S32: bunzl | T32: =87-59 -> 28 | U32: =28/95 -> 0.29473684
A34: This green area does not roll into other areas. This is | B34: Project Revenue - Agreements | C34: =7000+30000+87402 -> 124402 | D34: =40000+87402 -> 127402 | E34: =40000+87402 -> 127402 | F34: =40000+87402 -> 127402 | G34: =40000+87402 -> 127402 | H34: =40000+87402 -> 127402 | I34: =40000+87402 -> 127402 | J34: =40000+87402 -> 127402 | K34: =40000+87402 -> 127402 | L34: 135079 | M34: 135079 | N34: 135079 | O34: =SUM(C34:N34) -> 1548855
A35: a subset of AGREEMENT revenue. | B35: Project COGS Agreements (input) | C35: 75924 | D35: 78924 | E35: 78925 | F35: 78926 | G35: 78927 | H35: 78928 | I35: 78929 | J35: 78930 | K35: 78931 | L35: 78924 | M35: 78924 | N35: 78924 | O35: =SUM(C35:N35) -> 944116 | Q35: =SUM(Q27:Q33) -> 78924 | R35: =SUM(R27:R33) -> 135079
A36: Breakdown reporting only | B36: Project Agreement Margin $ | C36: =C34-C35 -> 48478 | D36: =D34-D35 -> 48478 | E36: =E34-E35 -> 48477 | F36: =F34-F35 -> 48476 | G36: =G34-G35 -> 48475 | H36: =H34-H35 -> 48474 | I36: =I34-I35 -> 48473 | J36: =J34-J35 -> 48472 | ... N36: =N34-N35 -> 56155 | O36: =SUM(C36:N36) -> 604739
B37: Project Agreement Margin % | C37: =C36/C34 -> 0.38968827 | D37: =D36/D34 -> 0.38051208 | E37: =E36/E34 -> 0.38050423 | F37: =F36/F34 -> 0.38049638 | G37: =G36/G34 -> 0.38048853 | H37: =H36/H34 -> 0.38048068 | I37: =I36/I34 -> 0.38047283 | J37: =J36/J34 -> 0.38046498 | ... O37: =O36/O34 -> 0.39044262 | Q37: =R35-Q35 -> 56155 | R37: =Q37/R35 -> 0.41571969
B38: Agreement Revenue | C38: =C3 -> 348558 | D38: =D3 -> 347041 | E38: =E3 -> 343646 | F38: =F3 -> 360526 | G38: =G3 -> 360034 | H38: =H3 -> 357860 | I38: =I3 -> 356659 | J38: =J3 -> 355372 | ... N38: =N3 -> 373130 | O38: =SUM(C38:N38) -> 4299071
B39: Agreement COGS (input) | C39: 113922 | D39: 125890 | E39: 115839 | F39: 115682 | G39: 117134 | H39: 117998 | I39: 119399 | J39: 117184 | K39: 118167 | L39: 122089 | M39: 122089 | N39: 123350 | O39: =SUM(C39:N39) -> 1428743
B40: Agreement Margin $ | C40: =C38-C39 -> 234636 | D40: =D38-D39 -> 221151 | E40: =E38-E39 -> 227807 | F40: =F38-F39 -> 244844 | G40: =G38-G39 -> 242900 | H40: =H38-H39 -> 239862 | I40: =I38-I39 -> 237260 | J40: =J38-J39 -> 238188 | ... N40: =N38-N39 -> 249780 | O40: =SUM(C40:N40) -> 2870328
B41: Agreement Margin % | C41: =C40/C38 -> 0.673162 | D41: =D40/D38 -> 0.63724747 | E41: =E40/E38 -> 0.66291183 | F41: =F40/F38 -> 0.67912994 | G41: =G40/G38 -> 0.6746585 | H41: =H40/H38 -> 0.6702677 | I41: =I40/I38 -> 0.66522925 | J41: =J40/J38 -> 0.67024977 | ... O41: =O40/O38 -> 0.66766239
B42: Standard Revenue (w Misc & CMs) | C42: =C10 -> 142362 | D42: =D10 -> 229434 | E42: =E10 -> 86779 | F42: =F10 -> 77612 | G42: =G10 -> 126216 | H42: =H10 -> 56715 | I42: =I10 -> 95800 | J42: =J10 -> 81425 | ... N42: =N10 -> 65199 | O42: =SUM(C42:N42) -> 1301155
B43: Standard Misc COGS (input) | C43: 108489 | D43: 126181 | E43: 28767 | F43: 42209 | G43: 76947 | H43: 37489 | I43: 52584 | J43: 55020 | K43: 96780 | L43: 87705 | M43: 31928 | N43: 39707 | O43: =SUM(C43:N43) -> 783806
...

Sheet 2023
A1: Today | B1: =TODAY() -> 46147 | G1: 2023
A2: Forecast | C2: Jan | D2: Feb | E2: Mar | F2: Apr | G2: May | H2: Jun | I2: Jul | J2: Aug | K2: Sept | L2: Oct | M2: Nov | N2: Dec | O2: YTD Total
A3: Recurring Sales Invoiced | B3: Agreement | C3: 218082 | D3: 216803 | E3: 231863 | F3: =233751+875 -> 234626 | G3: 252748 | H3: 275590 | I3: 303985 | J3: 304741 | K3: 324458 | L3: 371084 | M3: 373068 | N3: 338390 | O3: =SUM(C3:N3) -> 3445438
B4: Staff Aug Agreement | O4: =SUM(C4:N4) -> 0
B5: ITMS | O5: =SUM(C5:N5) -> 0
B6: Licensing | O6: =SUM(F6:N6) -> 0
B7: Staffing | O7: =SUM(C7:N7) -> 0
B8: Other | O8: =SUM(C8:N8) -> 0
A10: New Sales Invoiced [INPUTS] | B10: Standard - Invoiced | C10: 62639 | D10: 70350 | E10: =87494-10000 -> 77494 | F10: 51947 | G10: 140324 | H10: 165632 | I10: 72989 | J10: 150257 | K10: 103384 | L10: 93118 | M10: 64906 | N10: 59113 | O10: =SUM(C10:N10) -> 1112153
B11: Miscellaneous - Invoiced | D11: 656 | E11: 421 | F11: 1727 | G11: 2594 | H11: 625 | I11: 16128 | O11: =SUM(C11:N11) -> 22151
B12: Credit Memo - Invoiced | C12: -1183 | D12: -10069 | E12: -692 | G12: -12593 | H12: -2420 | O12: =SUM(C12:N12) -> -26957
A14: Pending and Projected Sales | B14: Pending Project Milestones | N14: 13143 | O14: =SUM(C14:N14) -> 13143
B15: Other Revenue | O15: =SUM(C15:N15) -> 0
B16: OPPS High Forecast (inputs)
B17: OPPS Low Forecast (inputs)
A19: Total | B19: Total Revenue | C19: =C3+C5+C6+C7+C8+C10+C11+C12+C14+C15 -> 279538 | D19: =D3+D5+D6+D7+D8+D10+D11+D12+D14+D15 -> 277740 | E19: =E3+E5+E6+E7+E8+E10+E11+E12+E14+E15 -> 309086 | F19: =F3+F4+F5+F6+F7+F8+F10+F11+F12+F14+F15 -> 288300 | G19: =G46 -> 383073 | H19: =H46 -> 439427 | I19: =I46 -> 393102 | J19: =J46 -> 454998 | K19: =K46 -> 427842 | L19: =L46 -> 464202 | M19: =M46 -> 437974 | N19: =N46 -> 397503 | O19: =SUM(C19:N19) -> 4552785 | R19: AGREEMENT
B20: High | C20: =C3+C5+C6+C10+C11+C16+C12 -> 279538 | D20: =D3+D5+D6+D10+D11+D16+D12 -> 277740 | E20: =E3+E5+E6+E10+E11+E16+E12+E14 -> 309086 | F20: =F19+F16 -> 288300 | G20: =G3+G5+G6+G10+G11+G16+G12+G14 -> 383073 | H20: =H3+H5+H6+H10+H11+H16+H12+H14 -> 439427 | I20: =I3+I5+I6+I10+I11+I16+I12+I14 -> 393102 | J20: =J3+J5+J6+J10+J11+J16+J12+J14 -> 454998 | K20: =K3+K5+K6+K7+K8+K10+K11+K12+K14+K16 -> 427842 | L20: =L3+L5+L6+L7+L8+L10+L11+L12+L14+L16 -> 464202 | M20: =M3+M5+M6+M7+M8+M10+M11+M12+M14+M16 -> 437974 | N20: =N3+N5+N6+N7+N8+N10+N11+N12+N14+N16 -> 410646 | R20: 373082 | S20: total
B21: Low | C21: =C3+C5+C6+C10+C11+C12+C17 -> 279538 | D21: =D3+D5+D6+D10+D11+D12+D17 -> 277740 | E21: =E3+E5+E6+E10+E11+E12+E17+E14 -> 309086 | F21: =F19+F17 -> 288300 | G21: =G3+G5+G6+G10+G11+G12+G17+G14 -> 383073 | H21: =H3+H5+H6+H10+H11+H12+H17+H14 -> 439427 | I21: =I3+I5+I6+I10+I11+I12+I17+I14 -> 393102 | J21: =J3+J5+J6+J10+J11+J12+J17+J14 -> 454998 | K21: =K3+K5+K6+K7+K8+K10+K11+K12+K14+K17 -> 427842 | L21: =L3+L5+L6+L7+L8+L10+L11+L12+L14+L17 -> 464202 | M21: =M3+M5+M6+M7+M8+M10+M11+M12+M14+M17 -> 437974 | N21: =N3+N5+N6+N7+N8+N10+N11+N12+N14+N17 -> 410646 | R21: 147395
A22: Gap (/mo) | B22: Revenue to Goal | C22: =C19-C25 -> -20462 | D22: =D19-D25 -> -32260 | E22: =E19-E25 -> -5914 | F22: =F19-F25 -> -31700 | G22: =G19-G25 -> 63073 | H22: =H19-H25 -> 84427 | I22: =I19-I25 -> 28102 | J22: =J19-J25 -> 54998 | ... N22: =N19-N25 -> -52497 | O22: =SUM(C22:N22) -> 117785 | R22: 176078
R23: =R20-R21-R22 -> 49609 | S23: Licensing
A24: Rolling Actual/Forecast | B24: Actual | C24: =C19 -> 279538 | D24: =C24+D19 -> 557278 | E24: =D24+E19 -> 866364 | F24: =E24+F19 -> 1154664 | G24: =F24+G19 -> 1537737 | H24: =G24+H19 -> 1977164 | I24: =H24+I19 -> 2370266 | J24: =I24+J19 -> 2825264 | K24: =J24+K19 -> 3253106 | ... N24: =M24+N19 -> 4552785 | O24: =N24 -> 4552785
A25: Monthly Goal | B25: Revenue GOAL | C25: 300000 | D25: 310000 | E25: 315000 | F25: 320000 | G25: 320000 | H25: 355000 | I25: 365000 | J25: 400000 | K25: 400000 | L25: 450000 | M25: 450000 | N25: 450000 | O25: =SUM(C25:N25) -> 4435000 | Q25: cogs | R25: rev
B26: Rolling GOAL | C26: =C25 -> 300000 | D26: =C26+D25 -> 610000 | E26: =D26+E25 -> 925000 | F26: =E26+F25 -> 1245000 | G26: =F26+G25 -> 1565000 | H26: =G26+H25 -> 1920000 | I26: =H26+I25 -> 2285000 | J26: =I26+J25 -> 2685000 | K26: =J26+K25 -> 3085000 | ... N26: =M26+N25 -> 4435000 | O26: =N26 -> 4435000 | Q26: 76493 | R26: 125395 | S26: arc
A27: Rolling Goal | C27: =C24-C26 -> -20462 | D27: =D24-D26 -> -52722 | E27: =E24-E26 -> -58636 | F27: =F24-F26 -> -90336 | G27: =G24-G26 -> -27263 | H27: =H24-H26 -> 57164 | I27: =I24-I26 -> 85266 | J27: =J24-J26 -> 140264 | ... N27: =N24-N26 -> 117785 | O27: =N27 -> 117785
A28: Rolling Goal | C28: Jan | D28: Feb | E28: Mar | F28: Apr | G28: May | H28: Jun | I28: Jul | J28: Aug | K28: Sept | L28: Oct | M28: Nov | N28: Dec | O28: 2019
A29: Rolling Goal | C29: =SUMIFS(#REF!,#REF!,1,#REF!,2019,#REF!,"open") -> #REF! | D29: =SUMIFS(#REF!,#REF!,2,#REF!,2019,#REF!,"open") -> #REF! | E29: =SUMIFS(#REF!,#REF!,3,#REF!,2019,#REF!,"open") -> #REF! | F29: =SUMIFS(#REF!,#REF!,4,#REF!,2019,#REF!,"open") -> #REF! | G29: =SUMIFS(#REF!,#REF!,5,#REF!,2019,#REF!,"open") -> #REF! | H29: =SUMIFS(#REF!,#REF!,6,#REF!,2019,#REF!,"open") -> #REF! | I29: =SUMIFS(#REF!,#REF!,7,#REF!,2019,#REF!,"open") -> #REF! | J29: =SUMIFS(#REF!,#REF!,8,#REF!,2019,#REF!,"open") -> #REF! | K29: =SUMIFS(#REF!,#REF!,9,#REF!,2019,#REF!,"open") -> #REF! | L29: =SUMIFS(#REF!,#REF!,10,#REF!,2019,#REF!,"open") -> #REF! | M29: =SUMIFS(#REF!,#REF!,11,#REF!,2019,#REF!,"open") -> #REF! | N29: =SUMIFS(#REF!,#REF!,12,#REF!,2019,#REF!,"open") -> #REF! | O29: =SUM(C29:N29) -> #REF!
A30: Rolling Goal | C30: =SUMIFS(#REF!,#REF!,1,#REF!,2019,#REF!,"*",#REF!,"open") -> #REF! | D30: =SUMIFS(#REF!,#REF!,2,#REF!,2019,#REF!,"*",#REF!,"open") -> #REF! | E30: =SUMIFS(#REF!,#REF!,3,#REF!,2019,#REF!,"*",#REF!,"open") -> #REF! | F30: =SUMIFS(#REF!,#REF!,4,#REF!,2019,#REF!,"*",#REF!,"open") -> #REF! | G30: =SUMIFS(#REF!,#REF!,5,#REF!,2019,#REF!,"*",#REF!,"open") -> #REF! | H30: =SUMIFS(#REF!,#REF!,6,#REF!,2019,#REF!,"*",#REF!,"open") -> #REF! | I30: =SUMIFS(#REF!,#REF!,7,#REF!,2019,#REF!,"*",#REF!,"open") -> #REF! | J30: =SUMIFS(#REF!,#REF!,8,#REF!,2019,#REF!,"*",#REF!,"open") -> #REF! | K30: =SUMIFS(#REF!,#REF!,9,#REF!,2019,#REF!,"*",#REF!,"open") -> #REF! | L30: =SUMIFS(#REF!,#REF!,10,#REF!,2019,#REF!,"*",#REF!,"open") -> #REF! | M30: =SUMIFS(#REF!,#REF!,11,#REF!,2019,#REF!,"*",#REF!,"open") -> #REF! | N30: =SUMIFS(#REF!,#REF!,12,#REF!,2019,#REF!,"*",#REF!,"open") -> #REF! | O30: =SUM(C30:N30) -> #REF!
B31: Rolling GOAL Difference | C31: =C24-C25 -> -20462 | D31: =D24-D26 -> -52722 | E31: =E24-E26 -> -58636 | F31: =F24-F26 -> -90336 | G31: =G24-G26 -> -27263 | H31: =H24-H26 -> 57164 | I31: =I24-I26 -> 85266 | J31: =J24-J26 -> 140264 | Q31: 7500 | R31: 15000 | S31: bunzl
Q32: 2000 | R32: 7000 | S32: rwb
A33: This green area does not roll into other areas. This is | B33: Project Revenue - Agreements | C33: 68800 | D33: 68800 | E33: 68800 | F33: 68800 | G33: 73645 | H33: =73645+7000 -> 80645 | I33: =73645+7000 -> 80645 | J33: =73645+7000 -> 80645 | K33: =73645+7000+20000 -> 100645 | L33: =125395+7000+15000 -> 147395 | M33: 147395 | N33: =87401+7000+15000 -> 109401 | O33: =SUM(C33:N33) -> 1095616
A34: a subset of AGREEMENT revenue. | B34: Project COGS Agreements (input) | C34: 41300 | D34: 41300 | E34: 41300 | F34: 41300 | G34: 49040 | H34: =41813+2200 -> 44013 | I34: =41813+2200 -> 44013 | J34: =41813+2200 -> 44013 | K34: 54000 | L34: 85993 | M34: 85993 | O34: =SUM(C34:N34) -> 572265 | Q34: =SUM(Q26:Q32) -> 85993 | R34: =SUM(R26:R32) -> 147395
A35: Breakdown reporting only | B35: Project Agreement Margin $ | C35: =C33-C34 -> 27500 | D35: =D33-D34 -> 27500 | E35: =E33-E34 -> 27500 | F35: =F33-F34 -> 27500 | G35: =G33-G34 -> 24605 | H35: =H33-H34 -> 36632 | I35: =I33-I34 -> 36632 | J35: =J33-J34 -> 36632 | ... N35: =N33-N34 -> 109401 | O35: =SUM(C35:N35) -> 523351
B36: Project Agreement Margin % | C36: =C35/C33 -> 0.3997093 | D36: =D35/D33 -> 0.3997093 | E36: =E35/E33 -> 0.3997093 | F36: =F35/F33 -> 0.3997093 | G36: =G35/G33 -> 0.33410279 | H36: =H35/H33 -> 0.45423771 | I36: =I35/I33 -> 0.45423771 | J36: =J35/J33 -> 0.45423771 | ... O36: =O35/O33 -> 0.4776774
B37: Agreement Revenue | C37: 221093 | D37: 220309 | E37: 235382 | F37: =F3 -> 234626 | G37: =G3 -> 252748 | H37: =H3 -> 275590 | I37: =I3 -> 303985 | J37: =J3 -> 304741 | K37: =K3 -> 324458 | L37: =L3 -> 371084 | M37: =M3 -> 373068 | N37: =N3 -> 338390 | O37: =SUM(C37:N37) -> 3455474 | R37: =125-87 -> 38
B38: Agreement COGS (input) | C38: 72816 | D38: 72895 | E38: 72704 | F38: 71598 | G38: 86053 | H38: 81568 | I38: 82196 | J38: 77141 | K38: 86887 | L38: 120216 | M38: 122384 | N38: 106649 | O38: =SUM(C38:N38) -> 1053107 | R38: =373-38 -> 335
B39: Agreement Margin $ | C39: =C37-C38 -> 148277 | D39: =D37-D38 -> 147414 | E39: =E37-E38 -> 162678 | F39: =F37-F38 -> 163028 | G39: =G37-G38 -> 166695 | H39: =H37-H38 -> 194022 | I39: =I37-I38 -> 221789 | J39: =J37-J38 -> 227600 | ... N39: =N37-N38 -> 231741 | O39: =SUM(C39:N39) -> 2402367
B40: Agreement Margin % | C40: =C39/C37 -> 0.67065443 | D40: =D39/D37 -> 0.66912382 | E40: =E39/E37 -> 0.69112337 | F40: =F39/F37 -> 0.694842 | G40: =G39/G37 -> 0.65953044 | H40: =H39/H37 -> 0.70402409 | I40: =I39/I37 -> 0.72960508 | J40: =J39/J37 -> 0.74686373 | ... O40: =O39/O37 -> 0.69523515
B41: Standard Revenue (w Misc & CMs) | C41: 57730 | D41: 59574 | E41: =97840-10000 -> 87840 | F41: =F10+F11+F12 -> 53674 | G41: =G10+G11+G12 -> 130325 | H41: =H10+H11+H12 -> 163837 | I41: =I10+I11+I12 -> 89117 | J41: =J10+J11+J12 -> 150257 | K41: =K10+K11+K12 -> 103384 | L41: =L10+L11+L12 -> 93118 | M41: =M10+M11+M12 -> 64906 | N41: =N10+N11+N12 -> 59113 | O41: =SUM(C41:N41) -> 1112875
B42: Standard Misc COGS (input) | C42: 47875 | D42: 40516 | E42: 68203 | F42: 24058 | G42: 82000 | H42: 100066 | I42: 47879 | J42: 107591 | K42: 72313 | L42: 50352 | M42: 33945 | N42: 41728 | O42: =SUM(C42:N42) -> 716526
B43: Standard Margin $ | C43: =C41-C42 -> 9855 | D43: =D41-D42 -> 19058 | E43: =E41-E42 -> 19637 | F43: =F41-F42 -> 29616 | G43: =G41-G42 -> 48325 | H43: =H41-H42 -> 63771 | I43: =I41-I42 -> 41238 | J43: =J41-J42 -> 42666 | ... N43: =N41-N42 -> 17385 | O43: =SUM(C43:N43) -> 396349
...

Sheet Categories
C1: Closed | D1: Forecast
A2: Service Name | B2: Type | D2: Jan | E2: Feb | F2: Mar | G2: Apr | H2: May | I2: Jun | J2: Jul | K2: Aug | L2: Sept | M2: Oct | N2: Nov | O2: Dec
A3: OLD BUSINESS
A4: ITMS Reoccurring (Help Desk, ITM) | B4: Monthly
A5: Hardware/Software Reoccurring (Amazon, SSaS) | B5: Monthly
A6: Service Management aaS (PM, SM) | B6: Monthly
A7: Pro Services (Staffed Reoccurring) | B7: Monthly
A8: Pro Services (Staffed Projects/Transactional) | B8: Transactional
A9: Pro Services (Outsourced Staffing) | B9: Transactional
A10: Pro Services (3rd Party) | B10: Transactional
A11: Hardware/Software Transactional | B11: Transactional
A12: HeroTech ITMS
A13: HeroTech Licenses
A14: HeroTech PM | B14: Monthly
A15: Other Services Income (RR, CareSight) | B15: Monthly
A17: NEW BUSINESS
A18: PC Refresh (POTS installed base) | C18: =SUMIFS(#REF!,#REF!,"POTS - PC Refresh 2019",#REF!,"won",#REF!,"<>Hero Tech") -> #REF! | D18: =SUMIFS(#REF!,#REF!,"POTS - PC Refresh 2019",#REF!,"open",#REF!,"1",#REF!,"<>Hero Tech") -> #REF! | E18: =SUMIFS(#REF!,#REF!,"POTS - PC Refresh 2019",#REF!,"open",#REF!,"2",#REF!,"<>Hero Tech") -> #REF! | F18: =SUMIFS(#REF!,#REF!,"POTS - PC Refresh 2019",#REF!,"open",#REF!,"3",#REF!,"<>Hero Tech") -> #REF! | G18: =SUMIFS(#REF!,#REF!,"POTS - PC Refresh 2019",#REF!,"open",#REF!,"4",#REF!,"<>Hero Tech") -> #REF! | H18: =SUMIFS(#REF!,#REF!,"POTS - PC Refresh 2019",#REF!,"open",#REF!,"5",#REF!,"<>Hero Tech") -> #REF! | I18: =SUMIFS(#REF!,#REF!,"POTS - PC Refresh 2019",#REF!,"open",#REF!,"6",#REF!,"<>Hero Tech") -> #REF! | J18: =SUMIFS(#REF!,#REF!,"POTS - PC Refresh 2019",#REF!,"open",#REF!,"7",#REF!,"<>Hero Tech") -> #REF! | K18: =SUMIFS(#REF!,#REF!,"POTS - PC Refresh 2019",#REF!,"open",#REF!,"8",#REF!,"<>Hero Tech") -> #REF! | L18: =SUMIFS(#REF!,#REF!,"POTS - PC Refresh 2019",#REF!,"open",#REF!,"9",#REF!,"<>Hero Tech") -> #REF! | M18: =SUMIFS(#REF!,#REF!,"POTS - PC Refresh 2019",#REF!,"open",#REF!,"10",#REF!,"<>Hero Tech") -> #REF! | N18: =SUMIFS(#REF!,#REF!,"POTS - PC Refresh 2019",#REF!,"open",#REF!,"11",#REF!,"<>Hero Tech") -> #REF! | O18: =SUMIFS(#REF!,#REF!,"POTS - PC Refresh 2019",#REF!,"open",#REF!,"12",#REF!,"<>Hero Tech") -> #REF!
A19: PC Refresh (HT installed base) | C19: =SUMIFS(#REF!,#REF!,"POTS - PC Refresh 2019",#REF!,"won",#REF!,"Hero Tech") -> #REF! | D19: =SUMIFS(#REF!,#REF!,"POTS - PC Refresh 2019",#REF!,"open",#REF!,"1",#REF!,"Hero Tech") -> #REF! | E19: =SUMIFS(#REF!,#REF!,"POTS - PC Refresh 2019",#REF!,"open",#REF!,"2",#REF!,"Hero Tech") -> #REF! | F19: =SUMIFS(#REF!,#REF!,"POTS - PC Refresh 2019",#REF!,"open",#REF!,"3",#REF!,"Hero Tech") -> #REF! | G19: =SUMIFS(#REF!,#REF!,"POTS - PC Refresh 2019",#REF!,"open",#REF!,"4",#REF!,"Hero Tech") -> #REF! | H19: =SUMIFS(#REF!,#REF!,"POTS - PC Refresh 2019",#REF!,"open",#REF!,"5",#REF!,"Hero Tech") -> #REF! | I19: =SUMIFS(#REF!,#REF!,"POTS - PC Refresh 2019",#REF!,"open",#REF!,"6",#REF!,"Hero Tech") -> #REF! | J19: =SUMIFS(#REF!,#REF!,"POTS - PC Refresh 2019",#REF!,"open",#REF!,"7",#REF!,"Hero Tech") -> #REF! | K19: =SUMIFS(#REF!,#REF!,"POTS - PC Refresh 2019",#REF!,"open",#REF!,"8",#REF!,"Hero Tech") -> #REF! | L19: =SUMIFS(#REF!,#REF!,"POTS - PC Refresh 2019",#REF!,"open",#REF!,"9",#REF!,"Hero Tech") -> #REF! | M19: =SUMIFS(#REF!,#REF!,"POTS - PC Refresh 2019",#REF!,"open",#REF!,"10",#REF!,"Hero Tech") -> #REF! | N19: =SUMIFS(#REF!,#REF!,"POTS - PC Refresh 2019",#REF!,"open",#REF!,"11",#REF!,"Hero Tech") -> #REF! | O19: =SUMIFS(#REF!,#REF!,"POTS - PC Refresh 2019",#REF!,"open",#REF!,"12",#REF!,"Hero Tech") -> #REF!
A20: POTS VoIP
A21: New ITMS Clients
A22: Other Campaigns (SQL, SBS, MS licenses)
D27: =D29/C29 -> 1.3639528 | E27: =E29/D29 -> 1.1955803 | F27: =F29/E29 -> 1.3087744 | G27: =G29/F29 -> 1.255967 | H27: =H29/G29 -> 1.1487822 | I27: =I29/H29 -> 0.84595948 | J27: =J29/I29 -> 1.1778695 | K27: =K29/J29 -> 1.1331328
C28: 2010 | D28: 2011 | E28: 2012 | F28: 2013 | G28: 2014 | H28: 2015 | I28: 2016 | J28: 2017 | K28: 2018
B29: POB | C29: 530937 | D29: 724173 | E29: 865807 | F29: 1133146 | G29: 1423194 | H29: 1634940 | I29: 1383093 | J29: 1629103 | K29: 1845990
B30: POTS | K30: 1696000
B31: Other | K31: =K29-K30 -> 149990

Sheet 5.1.18
G1: Yes | H1: Maybe | I1: No | J1: Notes
F2: May | G2: 45546.57 | H2: 45787.1 | I2: 70543.97 | J2: 91333.67
A4: Row Labels | B4: Opportunity Summary | C4: Years | D4: Stage | E4: Count of Company | F4: Sum of Revenue
A5: A Change in Trajectory (ACT) | B5: POTS PC Refresh | C5: 2019 | E5: 1 | F5: 22000
C6: Aug | E6: 1 | F6: 22000
C7: 31-Aug | D7: 5 - Solution Development | E7: 1 | F7: 22000 | J7: Update Amount, and update close date - past may
B8: POTS sonicwall renewal | C8: 2019 | E8: 2 | F8: 2000
C9: Feb | E9: 1 | F9: 400 | J9: Update Amount, and update close date - past may
C10: 20-Feb | D10: 13 - Needs Invoice | E10: 1 | F10: 400 | J10: Ask Amy if we can close this. Or move to 2017 close date
C11: Mar | E11: 1 | F11: 1600
C12: 13-Mar | D12: 13 - Needs Invoice | E12: 1 | F12: 1600 | G12: =GETPIVOTDATA("Sum of Revenue",$A$4,"Close Date",152,"Company","A Change in Trajectory (ACT)","Opportunity Summary","P1 Downtown location","Months",5) -> #REF! | J12: This week :)
B13: POTS Forever Social Cabling | C13: 2019 | E13: 1 | F13: 0 | G13: =GETPIVOTDATA("Sum of Revenue",$A$4,"Close Date",152,"Company","Advanced Chiropractic","Opportunity Summary","P1 Sonicwall License Renewal","Months",5) -> #REF! | J13: Need to invoice, update status of opp and ticket to needs invoice
C14: Feb | E14: 1 | F14: 0 | G14: =GETPIVOTDATA("Sum of Revenue",$A$4,"Close Date",125,"Company","Autism Behavioral Health (ABH)","Opportunity Summary","P1 snipping tool","Months",5) -> #REF!
C15: 28-Feb | D15: 90 - Lost | E15: 1 | F15: 0 | H15: =GETPIVOTDATA("Sum of Revenue",$A$4,"Close Date",152,"Company","CAPS MEDIA","Opportunity Summary","P1 PC Refresh - Win7 1 of 1","Months",5) -> #REF! | J15: Wait from info from client - internal challenge with their tech - need to f/u this week
B16: POTS Hive manager renewal | C16: 2019 | E16: 1 | F16: 525 | I16: =GETPIVOTDATA("Sum of Revenue",$A$4,"Close Date",152,"Company","Cool Pak","Opportunity Summary","P1 AWS - MS","Months",5) -> #REF! | J16: Update close date
C17: Feb | E17: 1 | F17: 525 | G17: =GETPIVOTDATA("Sum of Revenue",$A$4,"Close Date",125,"Company","DITEC Manufacturing","Opportunity Summary","P1 PC Refresh 1 of 6","Stage","Awaiting Client Approval","Months",5) -> #REF! | J17: need final client approval - Chad to call
C18: 18-Feb | D18: 13 - Needs Invoice | E18: 1 | F18: 525 | G18: =GETPIVOTDATA("Sum of Revenue",$A$4,"Close Date",142,"Company","DITEC Manufacturing","Opportunity Summary","P1 PC Refresh 2 of 6","Stage","New Opportunity","Months",5) -> #REF! | J18: need final client approval - Chad to call
B19: POTS Van Nuys Cable Add'l | C19: 2019 | E19: 1 | F19: 404.57 | I19: =GETPIVOTDATA("Sum of Revenue",$A$4,"Close Date",125,"Company","G and R Concrete","Opportunity Summary","P1 PC Refresh","Stage","New Opportunity","Months",5) -> #REF! | J19: update close date - confirm if "real"
C20: Jan | E20: 1 | F20: 404.57 | I20: =GETPIVOTDATA("Sum of Revenue",$A$4,"Close Date",152,"Company","Hod Dunbar","Opportunity Summary","P1 WiFI","Stage","New Opportunity","Months",5) -> #REF! | J20: June
C21: 21-Jan | D21: 13 - Needs Invoice | E21: 1 | F21: 404.57 | I21: =GETPIVOTDATA("Sum of Revenue",$A$4,"Close Date",152,"Company","House of Ruth","Opportunity Summary","P1 Laptop","Stage","New Opportunity","Months",5) -> #REF! | J21: Need to close opp, no sale
B22: POTS dual monitor | C22: 2019 | E22: 1 | F22: 132.97 | H22: =GETPIVOTDATA("Sum of Revenue",$A$4,"Close Date",125,"Company","House of Ruth","Opportunity Summary","P1 New Printer","Stage","New Opportunity","Months",5) -> #REF! | J22: Need to look into - call customer
C23: Mar | E23: 1 | F23: 132.97 | H23: =GETPIVOTDATA("Sum of Revenue",$A$4,"Close Date",152,"Company","House of Ruth","Opportunity Summary","P1 replace all computers HDD","Stage","Awaiting Client Approval","Months",5) -> #REF! | J23: Maybe for May - only 1 of these will come in. F/u with customer
C24: 31-Mar | D24: 13 - Needs Invoice | E24: 1 | F24: 132.97 | I24: =GETPIVOTDATA("Sum of Revenue",$A$4,"Close Date",152,"Company","House of Ruth","Opportunity Summary","P1 replace all computers SSD","Stage","Awaiting Client Approval","Months",5) -> #REF!
B25: POTS Adobe Acrobat DC licenses 32 exp 3/22 | C25: 2019 | E25: 1 | F25: 5660.9 | H25: =GETPIVOTDATA("Sum of Revenue",$A$4,"Close Date",125,"Company","Instrument Control Services","Opportunity Summary","P1 VoIP Proposal","Stage","New Opportunity","Months",5) -> #REF! | J25: Emo. Chad to follow up
C26: Mar | E26: 1 | F26: 5660.9 | I26: =GETPIVOTDATA("Sum of Revenue",$A$4,"Close Date",152,"Company","Jack Built","Opportunity Summary","P1 MS","Stage","Qualifying","Months",5) -> #REF! | J26: owner is going dark - potential new client
C27: 13-Mar | D27: 13 - Needs Invoice | E27: 1 | F27: 5660.9 | I27: =GETPIVOTDATA("Sum of Revenue",$A$4,"Close Date",152,"Company","Notes for Notes","Opportunity Summary","P1 iMac Hard Drive","Stage","On Hold","Months",5) -> #REF! | J27: Chad to f/u
B28: POTS Riverside Computers | C28: 2019 | E28: 1 | F28: 1739.66 | H28: =GETPIVOTDATA("Sum of Revenue",$A$4,"Close Date",152,"Company","Ojai Oil Company","Opportunity Summary","P1 AWS - test server","Stage","Awaiting Client Approval","Months",5) -> #REF! | J28: Testing thin client. Need to get someone onsite to set it up - sch this week
